/var/spool/slurmd/job26977702/slurm_script: line 3: module: command not found
mkdir: cannot create directory '/state/partition1/user/ywang5': File exists
> initializing model parallel with size 1
> initializing ddp with size 1
> initializing pipeline with size 1
[rank0]: Traceback (most recent call last):
[rank0]:   File "/home/gridsan/ywang5/projects/llm-context/evaluate_completions_llama.py", line 68, in <module>
[rank0]:     main()
[rank0]:   File "/home/gridsan/ywang5/projects/llm-context/evaluate_completions_llama.py", line 64, in main
[rank0]:     fire.Fire(run_main)
[rank0]:   File "/home/gridsan/ywang5/.local/lib/python3.9/site-packages/fire/core.py", line 143, in Fire
[rank0]:     component_trace = _Fire(component, args, parsed_flag_args, context, name)
[rank0]:   File "/home/gridsan/ywang5/.local/lib/python3.9/site-packages/fire/core.py", line 477, in _Fire
[rank0]:     component, remaining_args = _CallAndUpdateTrace(
[rank0]:   File "/home/gridsan/ywang5/.local/lib/python3.9/site-packages/fire/core.py", line 693, in _CallAndUpdateTrace
[rank0]:     component = fn(*varargs, **kwargs)
[rank0]:   File "/home/gridsan/ywang5/projects/llm-context/evaluate_completions_llama.py", line 32, in run_main
[rank0]:     generator = Llama.build(
[rank0]:   File "/home/gridsan/ywang5/projects/llm-context/llama/models/llama3/reference_impl/generation.py", line 129, in build
[rank0]:     tokenizer = Tokenizer(model_path=tokenizer_path)
[rank0]:   File "/home/gridsan/ywang5/projects/llm-context/llama/models/llama3/api/tokenizer.py", line 75, in __init__
[rank0]:     assert os.path.isfile(model_path), model_path
[rank0]: AssertionError: /home/gridsan/ywang5/projects/llama3/api/tokenizer.model
[rank0]:[W908 15:14:08.423089909 ProcessGroupNCCL.cpp:1168] Warning: WARNING: process group has NOT been destroyed before we destruct ProcessGroupNCCL. On normal program exit, the application should call destroy_process_group to ensure that any pending NCCL operations have finished in this process. In rare cases this process can exit before this point and block the progress of another member of the process group. This constraint has always been present,  but this warning has only been added since PyTorch 2.4 (function operator())
E0908 15:14:09.349330 140414074337088 torch/distributed/elastic/multiprocessing/api.py:833] failed (exitcode: 1) local_rank: 0 (pid: 1099063) of binary: /state/partition1/llgrid/pkg/anaconda/anaconda3-2023a/bin/python
Traceback (most recent call last):
  File "/home/gridsan/ywang5/.local/bin/torchrun", line 8, in <module>
    sys.exit(main())
  File "/home/gridsan/ywang5/.local/lib/python3.9/site-packages/torch/distributed/elastic/multiprocessing/errors/__init__.py", line 348, in wrapper
    return f(*args, **kwargs)
  File "/home/gridsan/ywang5/.local/lib/python3.9/site-packages/torch/distributed/run.py", line 901, in main
    run(args)
  File "/home/gridsan/ywang5/.local/lib/python3.9/site-packages/torch/distributed/run.py", line 892, in run
    elastic_launch(
  File "/home/gridsan/ywang5/.local/lib/python3.9/site-packages/torch/distributed/launcher/api.py", line 133, in __call__
    return launch_agent(self._config, self._entrypoint, list(args))
  File "/home/gridsan/ywang5/.local/lib/python3.9/site-packages/torch/distributed/launcher/api.py", line 264, in launch_agent
    raise ChildFailedError(
torch.distributed.elastic.multiprocessing.errors.ChildFailedError: 
============================================================
evaluate_completions_llama.py FAILED
------------------------------------------------------------
Failures:
  <NO_OTHER_FAILURES>
------------------------------------------------------------
Root Cause (first observed failure):
[0]:
  time      : 2024-09-08_15:14:09
  host      : d-7-15-2.supercloud.mit.edu
  rank      : 0 (local_rank: 0)
  exitcode  : 1 (pid: 1099063)
  error_file: <N/A>
  traceback : To enable traceback see: https://pytorch.org/docs/stable/elastic/errors.html
============================================================
